Workbook

Sheet Users
B1: Speccon
H2: Display Name | I2: Username | J2: Password
A3: Sales person | B3: SalesPersonAndebe1@test.co.za | C3: Sales Person 1 Andebe | E3: =SUBSTITUTE(B3,"Andebe","Megro") -> SalesPersonMegro1@test.co.za | F3: =SUBSTITUTE(C3,"Andebe","Megro") -> Sales Person 1 Megro | H3: Chandelle | I3: salesperson1@test.com | J3: Speccon1379!
B4: SalesPersonAndebe2@test.co.za | C4: Sales Person 2 Andebe | E4: =SUBSTITUTE(B4,"Andebe","Megro") -> SalesPersonMegro2@test.co.za | F4: =SUBSTITUTE(C4,"Andebe","Megro") -> Sales Person 2 Megro | H4: Glen | I4: salesperson2@test.com | J4: Speccon1379!
B5: SalesPersonAndebe3@test.co.za | C5: Sales Person 3 Andebe | E5: =SUBSTITUTE(B5,"Andebe","Megro") -> SalesPersonMegro3@test.co.za | F5: =SUBSTITUTE(C5,"Andebe","Megro") -> Sales Person 3 Megro | H5: Chantal | I5: salesperson3@test.com | J5: Speccon1379!
A7: Manager | B7: ManagerAndebe1@test.co.za | C7: Manager 1 Andebe | E7: =SUBSTITUTE(B7,"Andebe","Megro") -> ManagerMegro1@test.co.za | F7: =SUBSTITUTE(C7,"Andebe","Megro") -> Manager 1 Megro | H7: Pierre | I7: ManagerSpeccon@test.com | J7: Speccon
B8: ManagerAndebe2@test.co.za | C8: Manager 2 Andebe | E8: =SUBSTITUTE(B8,"Andebe","Megro") -> ManagerMegro2@test.co.za | F8: =SUBSTITUTE(C8,"Andebe","Megro") -> Manager 2 Megro | H8: Fred | I8: managertest@speccon.co.za | J8: Speccon1379!
A10: Admin | B10: AdminAndebe@test.co.za | C10: Admin Andebe | E10: =SUBSTITUTE(B10,"Andebe","Megro") -> AdminMegro@test.co.za | F10: =SUBSTITUTE(C10,"Andebe","Megro") -> Admin Megro | H10: hein@trouidees.co.za | I10: hein@trouidees.co.za | J10: Speccon1379!
A12: Group Sales manager | B12: GroupsalesManagerAndebe@test.co.za | C12: Group Manager Andebe | E12: =SUBSTITUTE(B12,"Andebe","Megro") -> GroupsalesManagerMegro@test.co.za | F12: =SUBSTITUTE(C12,"Andebe","Megro") -> Group Manager Megro | H12: Heinrich Sales person | I12: heinrichsalesperson@test.com | J12: Speccon1379!
A14: Accountant | B14: Andebeaccountant@test.com | C14: Andebe Accountant | E14: =SUBSTITUTE(B14,"Andebe","Megro") -> Megroaccountant@test.com | F14: =SUBSTITUTE(C14,"Andebe","Megro") -> Megro Accountant | H14: Speccon Accountant | I14: specconaccountant@test.com | J14: Speccon
H16: Name | I16: Role | J16: Username | K16: Password
H17: Hermias | I17: Group Sales Manager | J17: heinrichsalesperson@test.com | K17: Speccon1379!
A18: Email | B18: Display Name | C18: Password | D18: Dafault Role | H18: Pierre | I18: Sales Manager | J18: ManagerSpeccon@test.com | K18: Speccon
A19: SalesPersonInfinity1@test.co.za | B19: Sales Person 1 Infinity | C19: Speccon | D19: Sales Person | H19: Fred | I19: Sales Manager | J19: managertest@speccon.co.za | K19: Speccon1379!
A20: SalesPersonInfinity2@test.co.za | B20: Sales Person 2 Infinity | C20: Speccon | D20: Sales Person | H20: Thabani | I20: Accountant | J20: specconaccountant@test.com | K20: Speccon
A21: SalesPersonInfinity3@test.co.za | B21: Sales Person 3 Infinity | C21: Speccon | D21: Sales Person | H21: Chandelle | I21: Sales People | J21: salesperson1@test.com | K21: Speccon1379!
A22: ManagerInfinity1@test.co.za | B22: Manager 1 Infinity | C22: Speccon | D22: Manager | H22: Glen | I22: Sales People | J22: salesperson2@test.com | K22: Speccon1379!
A23: ManagerInfinity2@test.co.za | B23: Manager 2 Infinity | C23: Speccon | D23: Manager | H23: Chantal | I23: Sales People | J23: salesperson3@test.com | K23: Speccon1379!
A24: AdminInfinity@test.co.za | B24: Admin Infinity | C24: Speccon | D24: Admin | H24: Frans | I24: Sales People | J24: salesperson4@test.com | K24: Speccon
A25: GroupsalesManagerInfinity@test.co.za | B25: Group Manager Infinity | C25: Speccon | D25: Group Sales Managers | H25: Lucinda | I25: Sales People | J25: salesperson5@test.com | K25: Speccon
H26: Stephanie | I26: Sales People | J26: salesperson6@test.com | K26: Speccon

Sheet Test Data
E1: npx playwright test --project=e2e-setup --project=e2e-users --project=e2e-clients --project=e2e-forecasts --project=e2e-visibility --project=e2e-tenant-isolation --project=e2e-manager-isolation
A2: Tenant | B2: Clients | E2: npx playwright test tests/e2e/01-tenant-setup.spec.ts --project=e2e-setup
A3: Speccon
B4: Etion (S)
B5: AVI (S)
B6: The Digital Academy (S)
B7: Afgri (S)
B8: Komatsu (S)
A10: Megro
B11: Aberdare (M)
B12: Cure Day Hospitals (M)
B13: Bestmed (M)
B14: Mabilo Investments (M)
B15: Imperial Logistics (M)
B16: LSL Consulting (M)
B17: Ambledown Financial Services (M)
A19: Andebe
B20: Tribe Impact Consulting (A)
B21: Tanker Services a Diviosion of ILSA Group (A)
B22: EduLife (A)
B23: Triveni Turbines Africa (A)
B24: The Printer Distribution Company (A)
A27: New: Infinity
B28: Grand Gaming Gauteng (I)
B29: TNB Global (I)

Sheet PY-3
A1: Client Name | B1: Product Name | C1: Jan | D1: Feb | E1: Mar | F1: Apr | G1: May | H1: Jun | I1: Jul | J1: Aug | K1: Sept | L1: Oct | M1: Nov | N1: Dec
A2: Tech Solutions SA | B2: Other Courses | C2: 9138 | D2: 1517 | E2: 79142 | F2: 65749 | G2: 1780 | H2: 76631 | I2: 78420 | J2: 24088 | K2: 37438 | L2: 22236 | M2: 70583 | N2: 18542
A3: ABC Manufacturing | B3: Compliance Training | C3: 43753 | D3: 50181 | E3: 11954 | F3: 20387 | G3: 4613 | H3: 52862 | I3: 59258 | J3: 21761 | K3: 88380 | L3: 22742 | M3: 97518 | N3: 8904
A4: ABSA | B4: Learnerships | C4: 94189 | D4: 99333 | E4: 25781 | F4: 49049 | G4: 64407 | H4: 92515 | I4: 41104 | J4: 94769 | K4: 27497 | L4: 59193 | M4: 60192 | N4: 94503
A5: ABSA | B5: Compliance Training | C5: 63506 | D5: 81273 | E5: 49725 | F5: 25352 | G5: 38996 | H5: 15554 | I5: 77906 | J5: 86796 | K5: 55329 | L5: 28265 | M5: 59135 | N5: 84852
A6: Premier Academy | B6: Other Courses | C6: 97390 | D6: 26084 | E6: 80039 | F6: 55087 | G6: 40990 | H6: 13015 | I6: 56238 | J6: 75156 | K6: 71301 | L6: 64060 | M6: 78841 | N6: 35811
A7: Speccon | B7: TAP Business | C7: 7258 | D7: 41063 | E7: 14414 | F7: 87167 | G7: 59661 | H7: 39437 | I7: 15768 | J7: 53341 | K7: 92354 | L7: 43004 | M7: 90809 | N7: 71410
A8: AVI | B8: Compliance Training | C8: 54908 | D8: 90880 | E8: 11435 | F8: 33871 | G8: 18505 | H8: 97662 | I8: 55696 | J8: 9413 | K8: 82484 | L8: 41288 | M8: 8349 | N8: 61451
A9: Tech Solutions SA | B9: Learnerships | C9: 38260 | D9: 47838 | E9: 4974 | F9: 76621 | G9: 58829 | H9: 50521 | I9: 1019 | J9: 66841 | K9: 320 | L9: 81686 | M9: 66422 | N9: 48526
A10: Metro Logistics | B10: Compliance Training | C10: 25927 | D10: 45872 | E10: 6347 | F10: 19996 | G10: 19492 | H10: 8297 | I10: 25448 | J10: 51926 | K10: 11450 | L10: 31186 | M10: 38653 | N10: 27023
A11: AVI | B11: Learnerships | C11: 81036 | D11: 77363 | E11: 60532 | F11: 43129 | G11: 26424 | H11: 46771 | I11: 61150 | J11: 86862 | K11: 48290 | L11: 27969 | M11: 84329 | N11: 40266
A12: Greenfield High School | B12: Compliance Training | C12: 6333 | D12: 14621 | E12: 99633 | F12: 67398 | G12: 45837 | H12: 92864 | I12: 60525 | J12: 89615 | K12: 79960 | L12: 49979 | M12: 50054 | N12: 69936
A13: Speccon | B13: Other Courses | C13: 21786 | D13: 70127 | E13: 6333 | F13: 92239 | G13: 48518 | H13: 33200 | I13: 28391 | J13: 71380 | K13: 56255 | L13: 65222 | M13: 48641 | N13: 82722
... A33: AVI | B33: Other Courses | C33: 49346 | D33: 66321 | E33: 65012 | F33: 29771 | G33: 88963 | H33: 6028 | I33: 90784 | J33: 54941 | K33: 7203 | L33: 26863 | M33: 84143 | N33: 29431

Sheet PY-2
A1: Client Name | B1: Product Name | C1: Jan | D1: Feb | E1: Mar | F1: Apr | G1: May | H1: Jun | I1: Jul | J1: Aug | K1: Sept | L1: Oct | M1: Nov | N1: Dec
A2: Tech Solutions SA | B2: Learnerships | C2: 1967 | D2: 45170 | E2: 72298 | F2: 6758 | G2: 96800 | H2: 23834 | I2: 56220 | J2: 24071 | K2: 15100 | L2: 56077 | M2: 95329 | N2: 30236
A3: Speccon | B3: Other Courses | C3: 17514 | D3: 86441 | E3: 42209 | F3: 46051 | G3: 12005 | H3: 90366 | I3: 99214 | J3: 34262 | K3: 70875 | L3: 9849 | M3: 63014 | N3: 61375
A4: Premier Academy | B4: Other Courses | C4: 89416 | D4: 16886 | E4: 77480 | F4: 67251 | G4: 82651 | H4: 23575 | I4: 35164 | J4: 31586 | K4: 51185 | L4: 12232 | M4: 54200 | N4: 73612
A5: ABC Manufacturing | B5: Compliance Training | C5: 46867 | D5: 39193 | E5: 7321 | F5: 46072 | G5: 14209 | H5: 82167 | I5: 41795 | J5: 72227 | K5: 97311 | L5: 6948 | M5: 23515 | N5: 60705
A6: Metro Logistics | B6: TAP Business | C6: 34340 | D6: 25856 | E6: 6124 | F6: 69265 | G6: 77276 | H6: 81059 | I6: 71529 | J6: 57024 | K6: 38206 | L6: 51543 | M6: 74224 | N6: 77067
A7: ABC Manufacturing | B7: Other Courses | C7: 51512 | D7: 80804 | E7: 93527 | F7: 8988 | G7: 91669 | H7: 24742 | I7: 18549 | J7: 90598 | K7: 59165 | L7: 57828 | M7: 39853 | N7: 82596
A8: Speccon | B8: TAP Business | C8: 40294 | D8: 31966 | E8: 4506 | F8: 83899 | G8: 10470 | H8: 68370 | I8: 3069 | J8: 56024 | K8: 43082 | L8: 72813 | M8: 47421 | N8: 79169
A9: Tech Solutions SA | B9: Compliance Training | C9: 38800 | D9: 79645 | E9: 67054 | F9: 90135 | G9: 17571 | H9: 40884 | I9: 83383 | J9: 87642 | K9: 49316 | L9: 96829 | M9: 37293 | N9: 98106
A10: ABC Manufacturing | B10: TAP Business | C10: 32962 | D10: 11295 | E10: 48509 | F10: 67698 | G10: 16687 | H10: 6529 | I10: 23163 | J10: 50393 | K10: 11128 | L10: 20225 | M10: 70140 | N10: 34503
A11: AVI | B11: Learnerships | C11: 44986 | D11: 38503 | E11: 99496 | F11: 2557 | G11: 91411 | H11: 34107 | I11: 21838 | J11: 52163 | K11: 42891 | L11: 88871 | M11: 83356 | N11: 32016
A12: Premier Academy | B12: TAP Business | C12: 94387 | D12: 50965 | E12: 6492 | F12: 14142 | G12: 25296 | H12: 58072 | I12: 88136 | J12: 42438 | K12: 71393 | L12: 55235 | M12: 78388 | N12: 32938
A13: Premier Academy | B13: Learnerships | C13: 65163 | D13: 10055 | E13: 16779 | F13: 15509 | G13: 99542 | H13: 75868 | I13: 42155 | J13: 81621 | K13: 79595 | L13: 21390 | M13: 21301 | N13: 27469
... A28: Metro Logistics | B28: Other Courses | C28: 80116 | D28: 11740 | E28: 47807 | F28: 43990 | G28: 77790 | H28: 20704 | I28: 39521 | J28: 10486 | K28: 51166 | L28: 21500 | M28: 61646 | N28: 49427

Sheet PY-1
A1: Client Name | B1: Product Name | C1: Jan | D1: Feb | E1: Mar | F1: Apr | G1: May | H1: Jun | I1: Jul | J1: Aug | K1: Sept | L1: Oct | M1: Nov | N1: Dec
A2: Premier Academy | B2: Learnerships | C2: 86668 | D2: 53886 | E2: 57958 | F2: 12816 | G2: 16718 | H2: 98539 | I2: 7259 | J2: 17400 | K2: 28281 | L2: 69741 | M2: 85941 | N2: 87535
A3: ABC Manufacturing | B3: Learnerships | C3: 86724 | D3: 19027 | E3: 8960 | F3: 70952 | G3: 96431 | H3: 74451 | I3: 13212 | J3: 79721 | K3: 21558 | L3: 10329 | M3: 38972 | N3: 22230
A4: Speccon | B4: Learnerships | C4: 23769 | D4: 11768 | E4: 92636 | F4: 97495 | G4: 62683 | H4: 1110 | I4: 40640 | J4: 7503 | K4: 31313 | L4: 1392 | M4: 15905 | N4: 73944
A5: Premier Academy | B5: TAP Business | C5: 92521 | D5: 89792 | E5: 866 | F5: 33570 | G5: 86750 | H5: 29535 | I5: 9250 | J5: 40344 | K5: 87717 | L5: 19757 | M5: 98512 | N5: 28437
A6: Premier Academy | B6: Other Courses | C6: 96531 | D6: 72509 | E6: 5501 | F6: 44975 | G6: 40336 | H6: 20414 | I6: 76175 | J6: 81807 | K6: 80676 | L6: 80175 | M6: 817 | N6: 91983
A7: Metro Logistics | B7: Other Courses | C7: 27071 | D7: 27158 | E7: 81287 | F7: 52572 | G7: 36692 | H7: 64136 | I7: 15661 | J7: 76738 | K7: 72365 | L7: 85212 | M7: 62780 | N7: 40155
A8: Speccon | B8: Other Courses | C8: 43699 | D8: 22255 | E8: 36994 | F8: 43847 | G8: 34776 | H8: 49779 | I8: 63079 | J8: 77418 | K8: 25161 | L8: 90840 | M8: 37173 | N8: 84142
A9: Metro Logistics | B9: TAP Business | C9: 60573 | D9: 48884 | E9: 3963 | F9: 65576 | G9: 7898 | H9: 40048 | I9: 53819 | J9: 57555 | K9: 93091 | L9: 76652 | M9: 72274 | N9: 79633
A10: Metro Logistics | B10: Learnerships | C10: 69159 | D10: 57907 | E10: 39444 | F10: 91246 | G10: 5674 | H10: 10899 | I10: 84163 | J10: 26820 | K10: 50748 | L10: 753 | M10: 22087 | N10: 74365
A11: ABC Manufacturing | B11: TAP Business | C11: 86096 | D11: 63697 | E11: 84931 | F11: 44311 | G11: 94733 | H11: 47522 | I11: 74560 | J11: 86655 | K11: 62365 | L11: 34220 | M11: 18235 | N11: 66265
A12: Premier Academy | B12: Compliance Training | C12: 96146 | D12: 56189 | E12: 96188 | F12: 99668 | G12: 61410 | H12: 27852 | I12: 95420 | J12: 36487 | K12: 37266 | L12: 60747 | M12: 48071 | N12: 70787
A13: ABC Manufacturing | B13: Other Courses | C13: 92181 | D13: 51739 | E13: 74041 | F13: 17878 | G13: 26755 | H13: 99439 | I13: 34118 | J13: 70972 | K13: 52318 | L13: 69160 | M13: 58427 | N13: 47282
... A27: AVI | B27: TAP Business | C27: 82570 | D27: 14786 | E27: 10089 | F27: 15911 | G27: 19198 | H27: 90447 | I27: 53488 | J27: 99695 | K27: 27314 | L27: 2403 | M27: 17670 | N27: 33926

Sheet Budget
A1: Client Name | B1: Product Name | C1: Jan | D1: Feb | E1: Mar | F1: Apr | G1: May | H1: Jun | I1: Jul | J1: Aug | K1: Sept | L1: Oct | M1: Nov | N1: Dec
A2: Premier Academy | B2: TAP Business | C2: 95335 | D2: 59275 | E2: 63754 | F2: 14098 | G2: 18390 | H2: 108393 | I2: 7985 | J2: 19140 | K2: 31109 | L2: 76715 | M2: 94535 | N2: 96289
A3: Metro Logistics | B3: Other Courses | C3: 95396 | D3: 20930 | E3: 9856 | F3: 78047 | G3: 106074 | H3: 81896 | I3: 14533 | J3: 87693 | K3: 23714 | L3: 11362 | M3: 42869 | N3: 24453
A4: INVESTEC | B4: Other Courses | C4: 26146 | D4: 12945 | E4: 101900 | F4: 107245 | G4: 68951 | H4: 1221 | I4: 44704 | J4: 8253 | K4: 34444 | L4: 1531 | M4: 17496 | N4: 81338
A5: STND BANK | B5: Other Courses | C5: 80188 | D5: 75123 | E5: 107225 | F5: 14727 | G5: 23936 | H5: 13361 | I5: 20875 | J5: 93944 | K5: 55759 | L5: 77022 | M5: 14416 | N5: 85281
A6: Greenfield High School | B6: TAP Business | C6: 101773 | D6: 98771 | E6: 953 | F6: 36927 | G6: 95425 | H6: 32489 | I6: 10175 | J6: 44378 | K6: 96489 | L6: 21733 | M6: 108363 | N6: 31281
A7: Premier Academy | B7: Compliance Training | C7: 10600 | D7: 22290 | E7: 77574 | F7: 13127 | G7: 48337 | H7: 53851 | I7: 24176 | J7: 60474 | K7: 40229 | L7: 104092 | M7: 12170 | N7: 36185
A8: ABC Manufacturing | B8: Compliance Training | C8: 29778 | D8: 29874 | E8: 89416 | F8: 57829 | G8: 40361 | H8: 70550 | I8: 17227 | J8: 84412 | K8: 79602 | L8: 93733 | M8: 69058 | N8: 44171
A9: ABC Manufacturing | B9: Other Courses | C9: 48069 | D9: 24481 | E9: 40693 | F9: 48232 | G9: 38254 | H9: 54757 | I9: 69387 | J9: 85160 | K9: 27677 | L9: 99924 | M9: 40890 | N9: 92556
A10: AVI | B10: Other Courses | C10: 66630 | D10: 53772 | E10: 4359 | F10: 72134 | G10: 8688 | H10: 44053 | I10: 59201 | J10: 63311 | K10: 102400 | L10: 84317 | M10: 79501 | N10: 87596
A11: FNB | B11: Compliance Training | C11: 76075 | D11: 63698 | E11: 43388 | F11: 100371 | G11: 6241 | H11: 11989 | I11: 92579 | J11: 29502 | K11: 55823 | L11: 828 | M11: 24296 | N11: 81802
A12: STND BANK | B12: TAP Business | C12: 108637 | D12: 19549 | E12: 72415 | F12: 75473 | G12: 39613 | H12: 17974 | I12: 107731 | J12: 13574 | K12: 29102 | L12: 54981 | M12: 107830 | N12: 63026
A13: AVI | B13: Learnerships | C13: 105761 | D13: 61808 | E13: 105807 | F13: 109635 | G13: 67551 | H13: 30637 | I13: 104962 | J13: 40136 | K13: 40993 | L13: 66822 | M13: 52878 | N13: 77866
... A39: STND BANK | B39: Learnerships | C39: 103233 | D39: 66779 | E39: 94153 | F39: 41720 | G39: 4624 | H39: 101849 | I39: 49943 | J39: 14136 | K39: 72456 | L39: 66296 | M39: 79523 | N39: 1477

Sheet YTD
A1: Client Name | B1: Product Name | C1: Jan | D1: Feb | E1: Mar | F1: Apr | G1: May | H1: Jun | I1: Jul | J1: Aug | K1: Sept | L1: Oct | M1: Nov | N1: Dec
A2: Tech Solutions SA | B2: Learnerships | C2: 85576 | D2: 83179 | E2: 43987 | F2: 46761 | G2: 18441 | H2: 84378 | I2: 35852 | J2: 36721 | K2: 89058 | L2: 399 | M2: 47572
A3: Speccon | B3: Other Courses | C3: 62103 | D3: 22434 | E3: 43703 | F3: 80641 | G3: 24230 | H3: 18096 | I3: 28022 | J3: 97357 | K3: 79984 | L3: 31792 | M3: 49187
A4: Premier Academy | B4: Other Courses | C4: 12790 | D4: 17079 | E4: 37030 | F4: 95657 | G4: 59141 | H4: 37526 | I4: 26964 | J4: 19321 | K4: 17404 | L4: 69521 | M4: 46793
A5: ABC Manufacturing | B5: Compliance Training | C5: 62697 | D5: 6087 | E5: 17642 | F5: 78030 | G5: 66430 | H5: 97798 | I5: 39314 | J5: 35120 | K5: 69732 | L5: 34919 | M5: 25771
A6: Metro Logistics | B6: TAP Business | C6: 40534 | D6: 25371 | E6: 63307 | F6: 70284 | G6: 14580 | H6: 61248 | I6: 4731 | J6: 5744 | K6: 23965 | L6: 45809 | M6: 65650
A7: ABC Manufacturing | B7: Other Courses | C7: 2040 | D7: 49460 | E7: 27820 | F7: 30561 | G7: 57945 | H7: 50720 | I7: 65968 | J7: 26689 | K7: 4529 | L7: 47092 | M7: 3416
A8: Speccon | B8: TAP Business | C8: 75184 | D8: 78447 | E8: 55200 | F8: 14112 | G8: 83472 | H8: 27065 | I8: 27958 | J8: 98188 | K8: 36046 | L8: 76443 | M8: 88170
A9: Tech Solutions SA | B9: Compliance Training | C9: 24512 | D9: 47551 | E9: 12787 | F9: 51267 | G9: 15518 | H9: 48335 | I9: 74564 | J9: 93865 | K9: 84120 | L9: 29609 | M9: 35836
A10: ABC Manufacturing | B10: TAP Business | C10: 2166 | D10: 61813 | E10: 48075 | F10: 59678 | G10: 79746 | H10: 34915 | I10: 20624 | J10: 87149 | K10: 21793 | L10: 71435 | M10: 17258
A11: AVI | B11: Learnerships | C11: 23732 | D11: 89035 | E11: 69362 | F11: 94433 | G11: 28942 | H11: 62043 | I11: 35597 | J11: 54787 | K11: 18837 | L11: 65020 | M11: 87738
A12: Premier Academy | B12: TAP Business | C12: 66156 | D12: 85686 | E12: 58799 | F12: 49513 | G12: 45704 | H12: 32649 | I12: 72168 | J12: 20873 | K12: 3943 | L12: 44577 | M12: 38102
A13: Premier Academy | B13: Learnerships | C13: 83650 | D13: 60342 | E13: 2990 | F13: 73325 | G13: 48420 | H13: 1716 | I13: 45910 | J13: 17938 | K13: 94153 | L13: 6773 | M13: 98630
... A28: Metro Logistics | B28: Other Courses | C28: 44290 | D28: 48498 | E28: 24444 | F28: 73072 | G28: 65642 | H28: 57768 | I28: 94158 | J28: 46250 | K28: 49466 | L28: 25549 | M28: 79042

Sheet Summary
C1: 45352 | D1: =EOMONTH(C1,1) -> 45412 | E1: =EOMONTH(D1,1) -> 45443 | F1: =EOMONTH(E1,1) -> 45473 | G1: =EOMONTH(F1,1) -> 45504 | H1: =EOMONTH(G1,1) -> 45535 | I1: =EOMONTH(H1,1) -> 45565 | J1: =EOMONTH(I1,1) -> 45596 | K1: =EOMONTH(J1,1) -> 45626 | ... N1: =EOMONTH(M1,1) -> 45716
A2: Client Name | B2: Product Name | C2: Month 1 | D2: Month 2 | E2: Month 3 | F2: Month 4 | G2: Month 5 | H2: Month 6 | I2: Month 7 | J2: Month 8 | K2: Month 9 | L2: Month 10 | M2: Month 11 | N2: Month 12 | O2: Total | P2: YTD | Q2: Source | S2: Sum of Total | T2: Column Labels
A3: ='PY-3'!A2 -> Tech Solutions SA | B3: ='PY-3'!B2 -> Other Courses | C3: ='PY-3'!C2 -> 9138 | D3: ='PY-3'!D2 -> 1517 | E3: ='PY-3'!E2 -> 79142 | F3: ='PY-3'!F2 -> 65749 | G3: ='PY-3'!G2 -> 1780 | H3: ='PY-3'!H2 -> 76631 | ... N3: ='PY-3'!N2 -> 18542 | O3: =SUM(C3:N3) -> 485264 | P3: =O3-SUM(K3:N3) -> 336465 | Q3: PY-3 | S3: Row Labels | T3: YTD | U3: Budget | V3: PY-1 | W3: PY-2 | X3: PY-3
A4: ='PY-3'!A3 -> ABC Manufacturing | B4: ='PY-3'!B3 -> Compliance Training | C4: ='PY-3'!C3 -> 43753 | D4: ='PY-3'!D3 -> 50181 | E4: ='PY-3'!E3 -> 11954 | F4: ='PY-3'!F3 -> 20387 | G4: ='PY-3'!G3 -> 4613 | H4: ='PY-3'!H3 -> 52862 | ... N4: ='PY-3'!N3 -> 8904 | O4: =SUM(C4:N4) -> 482313 | P4: =O4-SUM(K4:N4) -> 264769 | Q4: =Q3 -> PY-3 | S4: ABSA | X4: 2584472
A5: ='PY-3'!A4 -> ABSA | B5: ='PY-3'!B4 -> Learnerships | C5: ='PY-3'!C4 -> 94189 | D5: ='PY-3'!D4 -> 99333 | E5: ='PY-3'!E4 -> 25781 | F5: ='PY-3'!F4 -> 49049 | G5: ='PY-3'!G4 -> 64407 | H5: ='PY-3'!H4 -> 92515 | ... N5: ='PY-3'!N4 -> 94503 | O5: =SUM(C5:N5) -> 802532 | P5: =O5-SUM(K5:N5) -> 561147 | Q5: =Q4 -> PY-3 | S5: FNB | U5: 2691131
A6: ='PY-3'!A5 -> ABSA | B6: ='PY-3'!B5 -> Compliance Training | C6: ='PY-3'!C5 -> 63506 | D6: ='PY-3'!D5 -> 81273 | E6: ='PY-3'!E5 -> 49725 | F6: ='PY-3'!F5 -> 25352 | G6: ='PY-3'!G5 -> 38996 | H6: ='PY-3'!H5 -> 15554 | ... N6: ='PY-3'!N5 -> 84852 | O6: =SUM(C6:N6) -> 666689 | P6: =O6-SUM(K6:N6) -> 439108 | Q6: =Q5 -> PY-3 | S6: INVESTEC | U6: 2649813
A7: ='PY-3'!A6 -> Premier Academy | B7: ='PY-3'!B6 -> Other Courses | C7: ='PY-3'!C6 -> 97390 | D7: ='PY-3'!D6 -> 26084 | E7: ='PY-3'!E6 -> 80039 | F7: ='PY-3'!F6 -> 55087 | G7: ='PY-3'!G6 -> 40990 | H7: ='PY-3'!H6 -> 13015 | ... N7: ='PY-3'!N6 -> 35811 | O7: =SUM(C7:N7) -> 694012 | P7: =O7-SUM(K7:N7) -> 443999 | Q7: =Q6 -> PY-3 | S7: STND BANK | U7: 2536457
A8: ='PY-3'!A7 -> Speccon | B8: ='PY-3'!B7 -> TAP Business | C8: ='PY-3'!C7 -> 7258 | D8: ='PY-3'!D7 -> 41063 | E8: ='PY-3'!E7 -> 14414 | F8: ='PY-3'!F7 -> 87167 | G8: ='PY-3'!G7 -> 59661 | H8: ='PY-3'!H7 -> 39437 | ... N8: ='PY-3'!N7 -> 71410 | O8: =SUM(C8:N8) -> 615686 | P8: =O8-SUM(K8:N8) -> 318109 | Q8: =Q7 -> PY-3 | S8: Tech Solutions SA | T8: 1771887 | U8: 2610565 | V8: 2736875 | W8: 1996849 | X8: 2161431
A9: ='PY-3'!A8 -> AVI | B9: ='PY-3'!B8 -> Compliance Training | C9: ='PY-3'!C8 -> 54908 | D9: ='PY-3'!D8 -> 90880 | E9: ='PY-3'!E8 -> 11435 | F9: ='PY-3'!F8 -> 33871 | G9: ='PY-3'!G8 -> 18505 | H9: ='PY-3'!H8 -> 97662 | ... N9: ='PY-3'!N8 -> 61451 | O9: =SUM(C9:N9) -> 565942 | P9: =O9-SUM(K9:N9) -> 372370 | Q9: =Q8 -> PY-3 | S9: ABC Manufacturing | T9: 2084641 | U9: 2792045 | V9: 2561631 | W9: 2269400 | X9: 2284355
A10: ='PY-3'!A9 -> Tech Solutions SA | B10: ='PY-3'!B9 -> Learnerships | C10: ='PY-3'!C9 -> 38260 | D10: ='PY-3'!D9 -> 47838 | E10: ='PY-3'!E9 -> 4974 | F10: ='PY-3'!F9 -> 76621 | G10: ='PY-3'!G9 -> 58829 | H10: ='PY-3'!H9 -> 50521 | ... N10: ='PY-3'!N9 -> 48526 | O10: =SUM(C10:N10) -> 541857 | P10: =O10-SUM(K10:N10) -> 344903 | Q10: =Q9 -> PY-3 | S10: Premier Academy | T10: 2179070 | U10: 2273122 | V10: 2717923 | W10: 2412158 | X10: 2402748
A11: ='PY-3'!A10 -> Metro Logistics | B11: ='PY-3'!B10 -> Compliance Training | C11: ='PY-3'!C10 -> 25927 | D11: ='PY-3'!D10 -> 45872 | E11: ='PY-3'!E10 -> 6347 | F11: ='PY-3'!F10 -> 19996 | G11: ='PY-3'!G10 -> 19492 | H11: ='PY-3'!H10 -> 8297 | ... N11: ='PY-3'!N10 -> 27023 | O11: =SUM(C11:N11) -> 311617 | P11: =O11-SUM(K11:N11) -> 203305 | Q11: =Q10 -> PY-3 | S11: Speccon | T11: 2433420 | U11: 2515175 | V11: 1786501 | W11: 2398913 | X11: 2402141
A12: ='PY-3'!A11 -> AVI | B12: ='PY-3'!B11 -> Learnerships | C12: ='PY-3'!C11 -> 81036 | D12: ='PY-3'!D11 -> 77363 | E12: ='PY-3'!E11 -> 60532 | F12: ='PY-3'!F11 -> 43129 | G12: ='PY-3'!G11 -> 26424 | H12: ='PY-3'!H11 -> 46771 | ... N12: ='PY-3'!N11 -> 40266 | O12: =SUM(C12:N12) -> 684121 | P12: =O12-SUM(K12:N12) -> 483267 | Q12: =Q11 -> PY-3 | S12: AVI | T12: 2076371 | U12: 2922855 | V12: 2353749 | W12: 2304532 | X12: 2456768
A13: ='PY-3'!A12 -> Greenfield High School | B13: ='PY-3'!B12 -> Compliance Training | C13: ='PY-3'!C12 -> 6333 | D13: ='PY-3'!D12 -> 14621 | E13: ='PY-3'!E12 -> 99633 | F13: ='PY-3'!F12 -> 67398 | G13: ='PY-3'!G12 -> 45837 | H13: ='PY-3'!H12 -> 92864 | ... N13: ='PY-3'!N12 -> 69936 | O13: =SUM(C13:N13) -> 726755 | P13: =O13-SUM(K13:N13) -> 476826 | Q13: =Q12 -> PY-3 | S13: Metro Logistics | T13: 2183654 | U13: 2274462 | V13: 1835058 | W13: 2478683 | X13: 2136834
A14: ='PY-3'!A13 -> Speccon | B14: ='PY-3'!B13 -> Other Courses | C14: ='PY-3'!C13 -> 21786 | D14: ='PY-3'!D13 -> 70127 | E14: ='PY-3'!E13 -> 6333 | F14: ='PY-3'!F13 -> 92239 | G14: ='PY-3'!G13 -> 48518 | H14: ='PY-3'!H13 -> 33200 | ... N14: ='PY-3'!N13 -> 82722 | O14: =SUM(C14:N14) -> 624814 | P14: =O14-SUM(K14:N14) -> 371974 | Q14: =Q13 -> PY-3 | S14: Greenfield High School | T14: 2492156 | U14: 2050814 | V14: 2367816 | W14: 2290462 | X14: 2676349
A15: ='PY-3'!A14 -> Premier Academy | B15: ='PY-3'!B14 -> Compliance Training | C15: ='PY-3'!C14 -> 91455 | D15: ='PY-3'!D14 -> 38360 | E15: ='PY-3'!E14 -> 40583 | F15: ='PY-3'!F14 -> 7086 | G15: ='PY-3'!G14 -> 8197 | H15: ='PY-3'!H14 -> 58082 | ... N15: ='PY-3'!N14 -> 51312 | O15: =SUM(C15:N15) -> 537400 | P15: =O15-SUM(K15:N15) -> 344467 | Q15: =Q14 -> PY-3 | S15: Grand Total | T15: 15221199 | U15: 25316439 | V15: 16359553 | W15: 16150997 | X15: 19105098
A16: ='PY-3'!A15 -> Metro Logistics | B16: ='PY-3'!B15 -> TAP Business | C16: ='PY-3'!C15 -> 84644 | D16: ='PY-3'!D15 -> 41594 | E16: ='PY-3'!E15 -> 75977 | F16: ='PY-3'!F15 -> 60817 | G16: ='PY-3'!G15 -> 10556 | H16: ='PY-3'!H15 -> 99400 | ... N16: ='PY-3'!N15 -> 69068 | O16: =SUM(C16:N16) -> 673579 | P16: =O16-SUM(K16:N16) -> 446240 | Q16: =Q15 -> PY-3
A17: ='PY-3'!A16 -> AVI | B17: ='PY-3'!B16 -> TAP Business | C17: ='PY-3'!C16 -> 22300 | D17: ='PY-3'!D16 -> 85109 | E17: ='PY-3'!E16 -> 7262 | F17: ='PY-3'!F16 -> 32601 | G17: ='PY-3'!G16 -> 74115 | H17: ='PY-3'!H16 -> 63195 | ... N17: ='PY-3'!N16 -> 59637 | O17: =SUM(C17:N17) -> 607899 | P17: =O17-SUM(K17:N17) -> 383989 | Q17: =Q16 -> PY-3 | T17: =SUM(T8:T10) -> 6035598 | U17: =SUM(U8:U10) -> 7675732 | V17: =SUM(V8:V10) -> 8016429 | W17: =SUM(W8:W10) -> 6678407 | X17: =SUM(X8:X10) -> 6848534
A18: ='PY-3'!A17 -> Tech Solutions SA | B18: ='PY-3'!B17 -> TAP Business | C18: ='PY-3'!C17 -> 71247 | D18: ='PY-3'!D17 -> 85496 | E18: ='PY-3'!E17 -> 41717 | F18: ='PY-3'!F17 -> 59602 | G18: ='PY-3'!G17 -> 79837 | H18: ='PY-3'!H17 -> 95439 | ... N18: ='PY-3'!N17 -> 72487 | O18: =SUM(C18:N18) -> 732008 | P18: =O18-SUM(K18:N18) -> 502491 | Q18: =Q17 -> PY-3
A19: ='PY-3'!A18 -> Greenfield High School | B19: ='PY-3'!B18 -> Learnerships | C19: ='PY-3'!C18 -> 67055 | D19: ='PY-3'!D18 -> 91926 | E19: ='PY-3'!E18 -> 91994 | F19: ='PY-3'!F18 -> 94246 | G19: ='PY-3'!G18 -> 79213 | H19: ='PY-3'!H18 -> 99776 | ... N19: ='PY-3'!N18 -> 36953 | O19: =SUM(C19:N19) -> 810384 | P19: =O19-SUM(K19:N19) -> 622279 | Q19: =Q18 -> PY-3
A20: ='PY-3'!A19 -> Tech Solutions SA | B20: ='PY-3'!B19 -> Compliance Training | C20: ='PY-3'!C19 -> 93669 | D20: ='PY-3'!D19 -> 57970 | E20: ='PY-3'!E19 -> 18170 | F20: ='PY-3'!F19 -> 76437 | G20: ='PY-3'!G19 -> 30660 | H20: ='PY-3'!H19 -> 64232 | ... N20: ='PY-3'!N19 -> 2946 | O20: =SUM(C20:N20) -> 402302 | P20: =O20-SUM(K20:N20) -> 356498 | Q20: =Q19 -> PY-3
A21: ='PY-3'!A20 -> Premier Academy | B21: ='PY-3'!B20 -> Learnerships | C21: ='PY-3'!C20 -> 15866 | D21: ='PY-3'!D20 -> 95702 | E21: ='PY-3'!E20 -> 30882 | F21: ='PY-3'!F20 -> 26927 | G21: ='PY-3'!G20 -> 17465 | H21: ='PY-3'!H20 -> 27495 | ... N21: ='PY-3'!N20 -> 42770 | O21: =SUM(C21:N21) -> 566934 | P21: =O21-SUM(K21:N21) -> 353585 | Q21: =Q20 -> PY-3
A22: ='PY-3'!A21 -> Greenfield High School | B22: ='PY-3'!B21 -> Other Courses | C22: ='PY-3'!C21 -> 68864 | D22: ='PY-3'!D21 -> 95319 | E22: ='PY-3'!E21 -> 35509 | F22: ='PY-3'!F21 -> 25206 | G22: ='PY-3'!G21 -> 37142 | H22: ='PY-3'!H21 -> 19641 | ... N22: ='PY-3'!N21 -> 82626 | O22: =SUM(C22:N22) -> 647075 | P22: =O22-SUM(K22:N22) -> 428569 | Q22: =Q21 -> PY-3
A23: ='PY-3'!A22 -> Metro Logistics | B23: ='PY-3'!B22 -> Other Courses | C23: ='PY-3'!C22 -> 68027 | D23: ='PY-3'!D22 -> 71055 | E23: ='PY-3'!E22 -> 50067 | F23: ='PY-3'!F22 -> 42679 | G23: ='PY-3'!G22 -> 62074 | H23: ='PY-3'!H22 -> 51214 | ... N23: ='PY-3'!N22 -> 31133 | O23: =SUM(C23:N23) -> 615020 | P23: =O23-SUM(K23:N23) -> 444007 | Q23: =Q22 -> PY-3
A24: ='PY-3'!A23 -> ABC Manufacturing | B24: ='PY-3'!B23 -> TAP Business | C24: ='PY-3'!C23 -> 36706 | D24: ='PY-3'!D23 -> 1096 | E24: ='PY-3'!E23 -> 21276 | F24: ='PY-3'!F23 -> 55989 | G24: ='PY-3'!G23 -> 30192 | H24: ='PY-3'!H23 -> 10206 | ... N24: ='PY-3'!N23 -> 13673 | O24: =SUM(C24:N24) -> 398520 | P24: =O24-SUM(K24:N24) -> 209091 | Q24: =Q23 -> PY-3
A25: ='PY-3'!A24 -> Metro Logistics | B25: ='PY-3'!B24 -> Learnerships | C25: ='PY-3'!C24 -> 17977 | D25: ='PY-3'!D24 -> 75707 | E25: ='PY-3'!E24 -> 19863 | F25: ='PY-3'!F24 -> 30875 | G25: ='PY-3'!G24 -> 61607 | H25: ='PY-3'!H24 -> 81053 | ... N25: ='PY-3'!N24 -> 9803 | O25: =SUM(C25:N25) -> 536618 | P25: =O25-SUM(K25:N25) -> 412673 | Q25: =Q24 -> PY-3
A26: ='PY-3'!A25 -> ABC Manufacturing | B26: ='PY-3'!B25 -> Other Courses | C26: ='PY-3'!C25 -> 93820 | D26: ='PY-3'!D25 -> 67428 | E26: ='PY-3'!E25 -> 67244 | F26: ='PY-3'!F25 -> 48128 | G26: ='PY-3'!G25 -> 53384 | H26: ='PY-3'!H25 -> 50430 | ... N26: ='PY-3'!N25 -> 40846 | O26: =SUM(C26:N26) -> 699264 | P26: =O26-SUM(K26:N26) -> 564516 | Q26: =Q25 -> PY-3 | S26: Sum of YTD | T26: Column Labels
A27: ='PY-3'!A26 -> ABSA | B27: ='PY-3'!B26 -> Other Courses | C27: ='PY-3'!C26 -> 61202 | D27: ='PY-3'!D26 -> 95255 | E27: ='PY-3'!E26 -> 33395 | F27: ='PY-3'!F26 -> 27800 | G27: ='PY-3'!G26 -> 33300 | H27: ='PY-3'!H26 -> 35040 | ... N27: ='PY-3'!N26 -> 64825 | O27: =SUM(C27:N27) -> 681891 | P27: =O27-SUM(K27:N27) -> 461174 | Q27: =Q26 -> PY-3 | S27: Row Labels | T27: YTD | U27: Budget | V27: PY-1 | W27: PY-2 | X27: PY-3
A28: ='PY-3'!A27 -> Speccon | B28: ='PY-3'!B27 -> Compliance Training | C28: ='PY-3'!C27 -> 83728 | D28: ='PY-3'!D27 -> 15762 | E28: ='PY-3'!E27 -> 7982 | F28: ='PY-3'!F27 -> 41529 | G28: ='PY-3'!G27 -> 78987 | H28: ='PY-3'!H27 -> 20325 | ... N28: ='PY-3'!N27 -> 63399 | O28: =SUM(C28:N28) -> 667266 | P28: =O28-SUM(K28:N28) -> 376754 | Q28: =Q27 -> PY-3 | S28: ABSA | X28: 1766165
A29: ='PY-3'!A28 -> ABC Manufacturing | B29: ='PY-3'!B28 -> Learnerships | C29: ='PY-3'!C28 -> 73495 | D29: ='PY-3'!D28 -> 28654 | E29: ='PY-3'!E28 -> 66709 | F29: ='PY-3'!F28 -> 70582 | G29: ='PY-3'!G28 -> 36804 | H29: ='PY-3'!H28 -> 82961 | ... N29: ='PY-3'!N28 -> 35967 | O29: =SUM(C29:N29) -> 704258 | P29: =O29-SUM(K29:N29) -> 459522 | Q29: =Q28 -> PY-3 | S29: FNB | U29: 1856963
A30: ='PY-3'!A29 -> Premier Academy | B30: ='PY-3'!B29 -> TAP Business | C30: ='PY-3'!C29 -> 32253 | D30: ='PY-3'!D29 -> 53684 | E30: ='PY-3'!E29 -> 98525 | F30: ='PY-3'!F29 -> 81214 | G30: ='PY-3'!G29 -> 21861 | H30: ='PY-3'!H29 -> 14585 | ... N30: ='PY-3'!N29 -> 88031 | O30: =SUM(C30:N30) -> 604402 | P30: =O30-SUM(K30:N30) -> 373630 | Q30: =Q29 -> PY-3 | S30: INVESTEC | U30: 1705148
A31: ='PY-3'!A30 -> Speccon | B31: ='PY-3'!B30 -> Learnerships | C31: ='PY-3'!C30 -> 61980 | D31: ='PY-3'!D30 -> 12972 | E31: ='PY-3'!E30 -> 6962 | F31: ='PY-3'!F30 -> 93709 | G31: ='PY-3'!G30 -> 3745 | H31: ='PY-3'!H30 -> 9524 | ... N31: ='PY-3'!N30 -> 77209 | O31: =SUM(C31:N31) -> 494375 | P31: =O31-SUM(K31:N31) -> 229520 | Q31: =Q30 -> PY-3 | S31: STND BANK | U31: 1664969
A32: ='PY-3'!A31 -> ABSA | B32: ='PY-3'!B31 -> TAP Business | C32: ='PY-3'!C31 -> 21489 | D32: ='PY-3'!D31 -> 16570 | E32: ='PY-3'!E31 -> 6744 | F32: ='PY-3'!F31 -> 10501 | G32: ='PY-3'!G31 -> 99090 | H32: ='PY-3'!H31 -> 36324 | ... N32: ='PY-3'!N31 -> 10605 | O32: =SUM(C32:N32) -> 433360 | P32: =O32-SUM(K32:N32) -> 304736 | Q32: =Q31 -> PY-3 | S32: Tech Solutions SA | T32: 1259553 | U32: 1772481 | V32: 1754995 | W32: 1296100 | X32: 1540357
A33: ='PY-3'!A32 -> Greenfield High School | B33: ='PY-3'!B32 -> TAP Business | C33: ='PY-3'!C32 -> 32054 | D33: ='PY-3'!D32 -> 3214 | E33: ='PY-3'!E32 -> 32468 | F33: ='PY-3'!F32 -> 21409 | G33: ='PY-3'!G32 -> 53795 | H33: ='PY-3'!H32 -> 23578 | ... N33: ='PY-3'!N32 -> 8018 | O33: =SUM(C33:N33) -> 492135 | P33: =O33-SUM(K33:N33) -> 340437 | Q33: =Q32 -> PY-3 | S33: ABC Manufacturing | T33: 1542185 | U33: 1717131 | V33: 1921881 | W33: 1507744 | X33: 1497898
A34: ='PY-3'!A33 -> AVI | B34: ='PY-3'!B33 -> Other Courses | C34: ='PY-3'!C33 -> 49346 | D34: ='PY-3'!D33 -> 66321 | E34: ='PY-3'!E33 -> 65012 | F34: ='PY-3'!F33 -> 29771 | G34: ='PY-3'!G33 -> 88963 | H34: ='PY-3'!H33 -> 6028 | ... N34: ='PY-3'!N33 -> 29431 | O34: =SUM(C34:N34) -> 598806 | P34: =O34-SUM(K34:N34) -> 451166 | Q34: =Q33 -> PY-3 | S34: Premier Academy | T34: 1616951 | U34: 1494626 | V34: 1741480 | W34: 1602190 | X34: 1515681
A35: ='PY-2'!A2 -> Tech Solutions SA | B35: ='PY-2'!B2 -> Learnerships | C35: ='PY-2'!C2 -> 1967 | D35: ='PY-2'!D2 -> 45170 | E35: ='PY-2'!E2 -> 72298 | F35: ='PY-2'!F2 -> 6758 | G35: ='PY-2'!G2 -> 96800 | H35: ='PY-2'!H2 -> 23834 | ... N35: ='PY-2'!N2 -> 30236 | O35: =SUM(C35:N35) -> 523860 | P35: =O35-SUM(K35:N35) -> 327118 | Q35: PY-2 | S35: Speccon | T35: 1721412 | U35: 1769635 | V35: 1148794 | W35: 1481305 | X35: 1296357
A36: ='PY-2'!A3 -> Speccon | B36: ='PY-2'!B3 -> Other Courses | C36: ='PY-2'!C3 -> 17514 | D36: ='PY-2'!D3 -> 86441 | E36: ='PY-2'!E3 -> 42209 | F36: ='PY-2'!F3 -> 46051 | G36: ='PY-2'!G3 -> 12005 | H36: ='PY-2'!H3 -> 90366 | ... N36: ='PY-2'!N3 -> 61375 | O36: =SUM(C36:N36) -> 633175 | P36: =O36-SUM(K36:N36) -> 428062 | Q36: =Q35 -> PY-2 | S36: AVI | T36: 1742981 | U36: 1847095 | V36: 1586230 | W36: 1378142 | X36: 1690792
A37: ='PY-2'!A4 -> Premier Academy | B37: ='PY-2'!B4 -> Other Courses | C37: ='PY-2'!C4 -> 89416 | D37: ='PY-2'!D4 -> 16886 | E37: ='PY-2'!E4 -> 77480 | F37: ='PY-2'!F4 -> 67251 | G37: ='PY-2'!G4 -> 82651 | H37: ='PY-2'!H4 -> 23575 | ... N37: ='PY-2'!N4 -> 73612 | O37: =SUM(C37:N37) -> 615238 | P37: =O37-SUM(K37:N37) -> 424009 | Q37: =Q36 -> PY-2 | S37: Metro Logistics | T37: 1500168 | U37: 1507820 | V37: 1104943 | W37: 1706064 | X37: 1506225
A38: ='PY-2'!A5 -> ABC Manufacturing | B38: ='PY-2'!B5 -> Compliance Training | C38: ='PY-2'!C5 -> 46867 | D38: ='PY-2'!D5 -> 39193 | E38: ='PY-2'!E5 -> 7321 | F38: ='PY-2'!F5 -> 46072 | G38: ='PY-2'!G5 -> 14209 | H38: ='PY-2'!H5 -> 82167 | ... N38: ='PY-2'!N5 -> 60705 | O38: =SUM(C38:N38) -> 538330 | P38: =O38-SUM(K38:N38) -> 349851 | Q38: =Q37 -> PY-2 | S38: Greenfield High School | T38: 1990987 | U38: 1313287 | V38: 1564473 | W38: 1621812 | X38: 1868111
A39: ='PY-2'!A6 -> Metro Logistics | B39: ='PY-2'!B6 -> TAP Business | C39: ='PY-2'!C6 -> 34340 | D39: ='PY-2'!D6 -> 25856 | E39: ='PY-2'!E6 -> 6124 | F39: ='PY-2'!F6 -> 69265 | G39: ='PY-2'!G6 -> 77276 | H39: ='PY-2'!H6 -> 81059 | ... N39: ='PY-2'!N6 -> 77067 | O39: =SUM(C39:N39) -> 663513 | P39: =O39-SUM(K39:N39) -> 422473 | Q39: =Q38 -> PY-2 | S39: Grand Total | T39: 11374237 | U39: 16649155 | V39: 10822796 | W39: 10593357 | X39: 12681586
A40: ='PY-2'!A7 -> ABC Manufacturing | B40: ='PY-2'!B7 -> Other Courses | C40: ='PY-2'!C7 -> 51512 | D40: ='PY-2'!D7 -> 80804 | E40: ='PY-2'!E7 -> 93527 | F40: ='PY-2'!F7 -> 8988 | G40: ='PY-2'!G7 -> 91669 | H40: ='PY-2'!H7 -> 24742 | ... N40: ='PY-2'!N7 -> 82596 | O40: =SUM(C40:N40) -> 699831 | P40: =O40-SUM(K40:N40) -> 460389 | Q40: =Q39 -> PY-2
...
